Delivered-To: meduardo.r@gmail.com
Received: by 2002:a5d:560c:0:0:0:0:0 with SMTP id l12-v6csp854544wrv;
        Wed, 26 Sep 2018 09:29:57 -0700 (PDT)
X-Received: by 2002:a25:8686:: with SMTP id z6-v6mr3517778ybk.398.1537979397020;
        Wed, 26 Sep 2018 09:29:57 -0700 (PDT)
ARC-Seal: i=1; a=rsa-sha256; t=1537979396; cv=none;
        d=google.com; s=arc-20160816;
        b=ZsjFutmvHjbIrtjvxlsjnyo8plAJhXW8wqx5rBaKu0FpjkDXeP5XuR5gjPJieqVQuZ
         5eZkNFtujOW98Ms6Lp0K2S9FgELEFEDNjyyWfJOp4n+BZSfSlHJPJPOSqcXzWl+pu/k9
         TFCKRKL8kvBXFsj9ksOLWU0HWjjVTllaOsbgC8k0hYTcIeID8jtK1ETOX2BxFTyiUon+
         ypEdyUqATpu65920EM42W5xyQWNqOE53JokR3xxiOfpjgcrWhs05D3XUiKRTnxp22xDe
         tS7Qfz0QfOOjKsIaWDkfjm4E0HWH4HW3iLfb1yTzf9yxGbBDObxZcq0g4u4IF5HO2GyW
         lPcQ==
ARC-Message-Signature: i=1; a=rsa-sha256; c=relaxed/relaxed; d=google.com; s=arc-20160816;
        h=list-unsubscribe:list-subscribe:list-archive:list-help:list-post
         :list-id:mailing-list:precedence:reply-to:mime-version:subject
         :message-id:to:from:date:sender:dkim-signature;
        bh=NfOyO0nVpOSye8DQu1cBT5v+Fsm6QT0E2Y4eumHlGRA=;
        b=ys6bsFFDsGJ3f40XvhHFs94jIqxm24wvoz7u7ep7ynw3vpj/K1ZIH31eRYTXm5wwSi
         EJG0Fov+zl6FZfp8OXJA3dxKhJzJJHq/7qenMeT65GaysZ0Bb00Fs/gmaK4K69PMEO/m
         vrcpQZsrKQXY92gd7fdtPu/cvYggivgwVbIGDeGzOXgrfGbAUJxMzQg/Gvgr8KW3L0PG
         NV+pOajqH1NsEmkCR1VhpVuN9QlBGFu3dzZAKpasx5UrBrJGKXDbFrE7kDnOuxOAhA5L
         0yFVBeinAuPkVDmn73tgCofo1KNvXzYy84XKzpXAe1Op3UPWJp9e7sqZqeEkFvD0T6Qg
         fS5g==
ARC-Authentication-Results: i=1; mx.google.com;
       dkim=pass header.i=@googlegroups.com header.s=20161025 header.b=AD7PyDDT;
       spf=pass (google.com: domain of python-brasil+bncbd26rvfzyairb7phv3oqkgqe5aba6gi@googlegroups.com designates 209.85.220.55 as permitted sender) smtp.mailfrom=python-brasil+bncBD26RVFZYAIRB7PHV3OQKGQE5ABA6GI@googlegroups.com;
       dmarc=fail (p=NONE sp=QUARANTINE dis=NONE) header.from=gmail.com
Return-Path: <python-brasil+bncBD26RVFZYAIRB7PHV3OQKGQE5ABA6GI@googlegroups.com>
Received: from mail-sor-f55.google.com (mail-sor-f55.google.com. [209.85.220.55])
        by mx.google.com with SMTPS id t192-v6sor336342ywg.217.2018.09.26.09.29.56
        (Google Transport Security);
        Wed, 26 Sep 2018 09:29:56 -0700 (PDT)
Received-SPF: pass (google.com: domain of python-brasil+bncbd26rvfzyairb7phv3oqkgqe5aba6gi@googlegroups.com designates 209.85.220.55 as permitted sender) client-ip=209.85.220.55;
Authentication-Results: mx.google.com;
       dkim=pass header.i=@googlegroups.com header.s=20161025 header.b=AD7PyDDT;
       spf=pass (google.com: domain of python-brasil+bncbd26rvfzyairb7phv3oqkgqe5aba6gi@googlegroups.com designates 209.85.220.55 as permitted sender) smtp.mailfrom=python-brasil+bncBD26RVFZYAIRB7PHV3OQKGQE5ABA6GI@googlegroups.com;
       dmarc=fail (p=NONE sp=QUARANTINE dis=NONE) header.from=gmail.com
DKIM-Signature: v=1; a=rsa-sha256; c=relaxed/relaxed;
        d=googlegroups.com; s=20161025;
        h=sender:date:from:to:message-id:subject:mime-version
         :x-original-sender:reply-to:precedence:mailing-list:list-id
         :list-post:list-help:list-archive:list-subscribe:list-unsubscribe;
        bh=NfOyO0nVpOSye8DQu1cBT5v+Fsm6QT0E2Y4eumHlGRA=;
        b=AD7PyDDTb44NoLoANO17sWXplHSJhghTkOwfQ8dLWZF+PqMTrYC/bJAeIg7CgtWOO6
         xGKM+M8zEKODfy4Zcm3m9XIoxCihyCX6JgszdNcJRNqf2jyTyX+U0RrNJ6nO2/MKLEtC
         OFwKldtcHbjVz15E6a0FYFUGe145WoLz9Vq3N206GP4T0khxiQrtZ0vht0AxO1GB34IT
         f0YNv5Qi45ZhykB5cSiYLTNIiJx33TAEND5JPsBHbqQXbvhpBTGVfpsiTFYY5JYNu7s+
         8jXjEEUC7rzq6LuT16TTKsNR2tNtW/RnnSAkVnnQ9xBYfAqM1likybSv1IFF7KFczHDI
         3pBg==
X-Google-DKIM-Signature: v=1; a=rsa-sha256; c=relaxed/relaxed;
        d=1e100.net; s=20161025;
        h=sender:x-gm-message-state:date:from:to:message-id:subject
         :mime-version:x-original-sender:reply-to:precedence:mailing-list
         :list-id:list-post:list-help:list-archive:list-subscribe
         :list-unsubscribe;
        bh=NfOyO0nVpOSye8DQu1cBT5v+Fsm6QT0E2Y4eumHlGRA=;
        b=hFp6a1EqROAj5VpNjc1ADzBQ2w+Hn2MRQWvIkEVEvsGueIdUvotp6u4MMuUJMDgeMN
         /IG2bJLkCd/FTNBU2Gf2S+hoSQefz0mPS1xU1lHwbwte7C7LDqPND/26b6d8gwohtLIB
         /ClAt3Z5WMxGYbD2qlyuYeNhrGpKC/RHs8uhdGbGpIkjrXnYzKko0LQO/U32tkDrUs7q
         7BF0JlVBdF7sZyG6Q0fUDOIyIkVvP7uJemMP22fhwA839txXNpYoqTbQbGLm22kmxLmR
         R7YXxm4Ak3iW9brYuZGlVU7Y/ZlSfYeU3cUHyi4gxSYk/BBrKMc6R1h5zH1EGE8TxWFi
         zYtQ==
Sender: python-brasil@googlegroups.com
X-Gm-Message-State: ABuFfoglkodTWTgjTD0bj7QBgAmDk291KDbtobNlME+vmCnLqU01DIur
	JU3lumXbJbM7yMpqKHC+SV0=
X-Google-Smtp-Source: ACcGV62jd8N6w9cEtuHdo4IYydZ2ZNKuqAtjOJfy2G8+mKoxlKAxemDzwfESxUdPeY3y08K9ZB/sSQ==
X-Received: by 2002:a0d:ea0b:: with SMTP id t11-v6mr76838ywe.6.1537979396400;
        Wed, 26 Sep 2018 09:29:56 -0700 (PDT)
X-BeenThere: python-brasil@googlegroups.com
Received: by 2002:a25:b942:: with SMTP id s2-v6ls713714ybm.17.gmail; Wed, 26
 Sep 2018 09:29:49 -0700 (PDT)
X-Received: by 2002:a25:5d6:: with SMTP id 205-v6mr647993ybf.52.1537979389647;
        Wed, 26 Sep 2018 09:29:49 -0700 (PDT)
Received: by 2002:a0d:cb0c:0:0:0:0:0 with SMTP id n12-v6msywd;
        Fri, 21 Sep 2018 13:09:00 -0700 (PDT)
X-Received: by 2002:a81:2b43:: with SMTP id r64-v6mr422695ywr.1.1537560540498;
        Fri, 21 Sep 2018 13:09:00 -0700 (PDT)
Date: Fri, 21 Sep 2018 13:09:00 -0700 (PDT)
From: Graciela Oliveira <graciela.oliveira@gmail.com>
To: Python Brasil <python-brasil@googlegroups.com>
Message-Id: <b2711e28-8529-4bb6-b3a9-79cd94043995@googlegroups.com>
Subject: [python-brasil] Biblioteca pyirt - Teoria da Resposta ao Item
MIME-Version: 1.0
Content-Type: multipart/mixed; 
	boundary="----=_Part_1092_1872254557.1537560540291"
X-Original-Sender: graciela.oliveira@gmail.com
Reply-To: python-brasil@googlegroups.com
Precedence: list
Mailing-list: list python-brasil@googlegroups.com; contact python-brasil+owners@googlegroups.com
List-ID: <python-brasil.googlegroups.com>
X-Google-Group-Id: 976534909641
List-Post: <https://groups.google.com/group/python-brasil/post>, <mailto:python-brasil@googlegroups.com>
List-Help: <https://groups.google.com/support/>, <mailto:python-brasil+help@googlegroups.com>
List-Archive: <https://groups.google.com/group/python-brasil
List-Subscribe: <https://groups.google.com/group/python-brasil/subscribe>, <mailto:python-brasil+subscribe@googlegroups.com>
List-Unsubscribe: <mailto:googlegroups-manage+976534909641+unsubscribe@googlegroups.com>,
 <https://groups.google.com/group/python-brasil/subscribe>

------=_Part_1092_1872254557.1537560540291
Content-Type: multipart/alternative; 
	boundary="----=_Part_1093_1766374657.1537560540292"

------=_Part_1093_1766374657.1537560540292
Content-Type: text/plain; charset="UTF-8"
Content-Transfer-Encoding: quoted-printable

Boa tarde,

Eu estou usando a biblioteca pyirt (https://github.com/17zuoye/pyirt) para=
=20
trabalhar com Teoria da Resposta ao item mas estou encontrando o erro=20
abaixo.
Algu=C3=A9m j=C3=A1 teve experi=C3=AAncia com essa biblioteca e pode me aju=
dar?

Obrigada!





from pyirt import irt
>>> scr_fp =3D [('11001138433007', '1', 1),('11001138433007', '2', 0)]
>>> item_param, user_param =3D irt(scr_fp)
2018-09-21 16:38:48 INFO: start loading data
start loading data
************************** ['11001138433007', '11001138433007'] ['1', '2']=
=20
[1, 0]
2018-09-21 16:38:48 INFO: data loaded
data loaded
100%|=E2=96=88=E2=96=88=E2=96=88=E2=96=88=E2=96=88=E2=96=88=E2=96=88=E2=96=
=88=E2=96=88=E2=96=88=E2=96=88=E2=96=88=E2=96=88=E2=96=88=E2=96=88=E2=96=88=
=E2=96=88=E2=96=88=E2=96=88=E2=96=88=E2=96=88=E2=96=88=E2=96=88=E2=96=88=E2=
=96=88=E2=96=88=E2=96=88=E2=96=88=E2=96=88=E2=96=88=E2=96=88=E2=96=88=E2=96=
=88=E2=96=88=E2=96=88=E2=96=88=E2=96=88=E2=96=88=E2=96=88=E2=96=88=E2=96=88=
=E2=96=88=E2=96=88=E2=96=88=E2=96=88=E2=96=88=E2=96=88=E2=96=88=E2=96=88=E2=
=96=88=E2=96=88=E2=96=88=E2=96=88=E2=96=88=E2=96=88=E2=96=88=E2=96=88=E2=96=
=88=E2=96=88=E2=96=88=E2=96=88=E2=96=88=E2=96=88=E2=96=88=E2=96=88=E2=96=88=
=E2=96=88=E2=96=88=E2=96=88=E2=96=88=E2=96=88=E2=96=88=E2=96=88=E2=96=88=E2=
=96=88=E2=96=88=E2=96=88=E2=96=88=E2=96=88=E2=96=88=E2=96=88=E2=96=88=E2=96=
=88=E2=96=88=E2=96=88=E2=96=88=E2=96=88=E2=96=88=E2=96=88=E2=96=88=E2=96=88=
=E2=96=88=E2=96=88=E2=96=88=E2=96=88=E2=96=88=E2=96=88=E2=96=88=E2=96=88=E2=
=96=88=E2=96=88=E2=96=88=E2=96=88=E2=96=88=E2=96=88=E2=96=88=E2=96=88=E2=96=
=88=E2=96=88=E2=96=88=E2=96=88=E2=96=88=E2=96=88=E2=96=88=E2=96=88=E2=96=88=
=E2=96=88=E2=96=88=E2=96=88=E2=96=88=E2=96=88=E2=96=88=E2=96=88=E2=96=88=E2=
=96=88=E2=96=88=E2=96=88=E2=96=88=E2=96=88=E2=96=88=E2=96=88=E2=96=88=E2=96=
=88=E2=96=88=E2=96=88=E2=96=88=E2=96=88=E2=96=88=E2=96=88=E2=96=88=E2=96=88=
=E2=96=88=E2=96=88=E2=96=88=E2=96=88=E2=96=88=E2=96=88=E2=96=88=E2=96=88=E2=
=96=88=E2=96=88=E2=96=88=E2=96=88=E2=96=88=E2=96=88=E2=96=88=E2=96=88=E2=96=
=88=E2=96=88=E2=96=88=E2=96=88=E2=96=88=E2=96=88=E2=96=88=E2=96=88=E2=96=88=
=E2=96=88=E2=96=88|=20
1/1 [00:00<00:00, 639.77it/s]
 =20
0%|                                                                        =
                                                                           =
                             =20
| 0/2 [00:00<?, ?it/s]6666666666666666666666666666666666666CHAMADAGET_MAP 0
TTTTTTTTTTTTTTTTTTTTTTTTTTTTTTGET_MAP3 ['1', '0']

--- Logging error ---
Traceback (most recent call last):
  File "/home/graciela/descomplica/pyirt/pyirt/pyirt/solver/model.py", line=
=20
368, in update
    map_user_idx_vec =3D self.dao.get_map(item_idx, ['1', '0'])
  File "/home/graciela/descomplica/pyirt/pyirt/pyirt/dao.py", line 152, in=
=20
get_map
    return [self.database.item2user_map[str(ans_key)][item_idx] for ans_key=
=20
in ans_key_list]
  File "/home/graciela/descomplica/pyirt/pyirt/pyirt/dao.py", line 152, in=
=20
<listcomp>
    return [self.database.item2user_map[str(ans_key)][item_idx] for ans_key=
=20
in ans_key_list]
KeyError: 0

During handling of the above exception, another exception occurred:

Traceback (most recent call last):
  File "/usr/lib/python3.6/logging/__init__.py", line 993, in emit
    msg =3D self.format(record)
  File "/usr/lib/python3.6/logging/__init__.py", line 839, in format
    return fmt.format(record)
  File "/usr/lib/python3.6/logging/__init__.py", line 576, in format
    record.message =3D record.getMessage()
  File "/usr/lib/python3.6/logging/__init__.py", line 338, in getMessage
    msg =3D msg % self.args
TypeError: not all arguments converted during string formatting
Call stack:
  File "<stdin>", line 1, in <module>
  File "/home/graciela/descomplica/pyirt/pyirt/pyirt/_pyirt.py", line 46,=
=20
in irt
    mod.solve_EM()
  File "/home/graciela/descomplica/pyirt/pyirt/pyirt/solver/model.py", line=
=20
101, in solve_EM
    self._exp_step()
  File "/home/graciela/descomplica/pyirt/pyirt/pyirt/solver/model.py", line=
=20
161, in _exp_step
    self.__get_expect_count()
  File "/home/graciela/descomplica/pyirt/pyirt/pyirt/solver/model.py", line=
=20
395, in __get_expect_count
    procs =3D procs_operator(procs, 7200, 0.1)
  File "/home/graciela/descomplica/pyirt/pyirt/pyirt/solver/model.py", line=
=20
27, in procs_operator
    p.start()
  File "/usr/lib/python3.6/multiprocessing/process.py", line 105, in start
    self._popen =3D self._Popen(self)
  File "/usr/lib/python3.6/multiprocessing/context.py", line 223, in _Popen
    return _default_context.get_context().Process._Popen(process_obj)
  File "/usr/lib/python3.6/multiprocessing/context.py", line 277, in _Popen
    return Popen(process_obj)
  File "/usr/lib/python3.6/multiprocessing/popen_fork.py", line 19, in=20
__init__
    self._launch(process_obj)
  File "/usr/lib/python3.6/multiprocessing/popen_fork.py", line 73, in=20
_launch
    code =3D process_obj._bootstrap()
  File "/usr/lib/python3.6/multiprocessing/process.py", line 258, in=20
_bootstrap
    self.run()
  File "/usr/lib/python3.6/multiprocessing/process.py", line 93, in run
    self._target(*self._args, **self._kwargs)
  File "/home/graciela/descomplica/pyirt/pyirt/pyirt/solver/model.py", line=
=20
374, in update
    self.logger.critical("Unexpected error:", str(e))
Message: 'Unexpected error:'
Arguments: ('0',)
--- Logging error ---
Traceback (most recent call last):
  File "/home/graciela/descomplica/pyirt/pyirt/pyirt/solver/model.py", line=
=20
368, in update
    map_user_idx_vec =3D self.dao.get_map(item_idx, ['1', '0'])
  File "/home/graciela/descomplica/pyirt/pyirt/pyirt/dao.py", line 152, in=
=20
get_map
    return [self.database.item2user_map[str(ans_key)][item_idx] for ans_key=
=20
in ans_key_list]
  File "/home/graciela/descomplica/pyirt/pyirt/pyirt/dao.py", line 152, in=
=20
<listcomp>
    return [self.database.item2user_map[str(ans_key)][item_idx] for ans_key=
=20
in ans_key_list]
KeyError: 0

During handling of the above exception, another exception occurred:

Traceback (most recent call last):
  File "/usr/lib/python3.6/logging/__init__.py", line 993, in emit
    msg =3D self.format(record)
  File "/usr/lib/python3.6/logging/__init__.py", line 839, in format
    return fmt.format(record)
  File "/usr/lib/python3.6/logging/__init__.py", line 576, in format
    record.message =3D record.getMessage()
  File "/usr/lib/python3.6/logging/__init__.py", line 338, in getMessage
    msg =3D msg % self.args
TypeError: not all arguments converted during string formatting
Call stack:
  File "<stdin>", line 1, in <module>
  File "/home/graciela/descomplica/pyirt/pyirt/pyirt/_pyirt.py", line 46,=
=20
in irt
    mod.solve_EM()
  File "/home/graciela/descomplica/pyirt/pyirt/pyirt/solver/model.py", line=
=20
101, in solve_EM
    self._exp_step()
  File "/home/graciela/descomplica/pyirt/pyirt/pyirt/solver/model.py", line=
=20
161, in _exp_step
    self.__get_expect_count()
  File "/home/graciela/descomplica/pyirt/pyirt/pyirt/solver/model.py", line=
=20
395, in __get_expect_count
    procs =3D procs_operator(procs, 7200, 0.1)
  File "/home/graciela/descomplica/pyirt/pyirt/pyirt/solver/model.py", line=
=20
27, in procs_operator
    p.start()
  File "/usr/lib/python3.6/multiprocessing/process.py", line 105, in start
    self._popen =3D self._Popen(self)
  File "/usr/lib/python3.6/multiprocessing/context.py", line 223, in _Popen
    return _default_context.get_context().Process._Popen(process_obj)
  File "/usr/lib/python3.6/multiprocessing/context.py", line 277, in _Popen
    return Popen(process_obj)
  File "/usr/lib/python3.6/multiprocessing/popen_fork.py", line 19, in=20
__init__
    self._launch(process_obj)
  File "/usr/lib/python3.6/multiprocessing/popen_fork.py", line 73, in=20
_launch
    code =3D process_obj._bootstrap()
  File "/usr/lib/python3.6/multiprocessing/process.py", line 258, in=20
_bootstrap
    self.run()
  File "/usr/lib/python3.6/multiprocessing/process.py", line 93, in run
    self._target(*self._args, **self._kwargs)
  File "/home/graciela/descomplica/pyirt/pyirt/pyirt/solver/model.py", line=
=20
374, in update
    self.logger.critical("Unexpected error:", str(e))
Message: 'Unexpected error:'
Arguments: ('0',)
Process Process-4:
Traceback (most recent call last):
  File "/usr/lib/python3.6/multiprocessing/process.py", line 258, in=20
_bootstrap
    self.run()
  File "/usr/lib/python3.6/multiprocessing/process.py", line 93, in run
    self._target(*self._args, **self._kwargs)
  File "/home/graciela/descomplica/pyirt/pyirt/pyirt/solver/model.py", line=
=20
375, in update
    raise e
  File "/home/graciela/descomplica/pyirt/pyirt/pyirt/solver/model.py", line=
=20
368, in update
    map_user_idx_vec =3D self.dao.get_map(item_idx, ['1', '0'])
  File "/home/graciela/descomplica/pyirt/pyirt/pyirt/dao.py", line 152, in=
=20
get_map
    return [self.database.item2user_map[str(ans_key)][item_idx] for ans_key=
=20
in ans_key_list]
  File "/home/graciela/descomplica/pyirt/pyirt/pyirt/dao.py", line 152, in=
=20
<listcomp>
    return [self.database.item2user_map[str(ans_key)][item_idx] for ans_key=
=20
in ans_key_list]
KeyError: 0
Traceback (most recent call last):
  File "<stdin>", line 1, in <module>
  File "/home/graciela/descomplica/pyirt/pyirt/pyirt/_pyirt.py", line 46,=
=20
in irt
    mod.solve_EM()
  File "/home/graciela/descomplica/pyirt/pyirt/pyirt/solver/model.py", line=
=20
101, in solve_EM
    self._exp_step()
  File "/home/graciela/descomplica/pyirt/pyirt/pyirt/solver/model.py", line=
=20
161, in _exp_step
    self.__get_expect_count()
  File "/home/graciela/descomplica/pyirt/pyirt/pyirt/solver/model.py", line=
=20
400, in __get_expect_count
    self.item_expected_right_by_theta[:, item_idx] =3D procs_repo[item_idx]=
[1]
  File "<string>", line 2, in __getitem__
  File "/usr/lib/python3.6/multiprocessing/managers.py", line 772, in=20
_callmethod
    raise convert_to_error(kind, result)
KeyError: 0

--=20
--=20
------------------------------------
Grupo Python-Brasil
https://wiki.python.org.br/AntesDePerguntar

<*> Para visitar o site do grupo na web, acesse:
    http://groups.google.com/group/python-brasil

<*> Para sair deste grupo, envie um e-mail para:
    python-brasil+unsubscribe@googlegroups.com
---=20
Voc=C3=AA est=C3=A1 recebendo esta mensagem porque se inscreveu no grupo "P=
ython Brasil" dos Grupos do Google.
Para cancelar inscri=C3=A7=C3=A3o nesse grupo e parar de receber e-mails de=
le, envie um e-mail para python-brasil+unsubscribe@googlegroups.com.
Para postar neste grupo, envie um e-mail para python-brasil@googlegroups.co=
m.
Para ver esta discuss=C3=A3o na web, acesse https://groups.google.com/d/msg=
id/python-brasil/b2711e28-8529-4bb6-b3a9-79cd94043995%40googlegroups.com.
Para obter mais op=C3=A7=C3=B5es, acesse https://groups.google.com/d/optout=
.

------=_Part_1093_1766374657.1537560540292
Content-Type: text/html; charset="UTF-8"
Content-Transfer-Encoding: quoted-printable

<div dir=3D"ltr"><div>Boa tarde,</div><div><br></div><div>Eu estou usando a=
 biblioteca pyirt (<a href=3D"https://github.com/17zuoye/pyirt">https://git=
hub.com/17zuoye/pyirt</a>) para trabalhar com Teoria da Resposta ao item ma=
s estou encontrando o erro abaixo.</div><div>Algu=C3=A9m j=C3=A1 teve exper=
i=C3=AAncia com essa biblioteca e pode me ajudar?</div><div><br>Obrigada!<b=
r><br><br><br><br><br>from pyirt import irt<br>&gt;&gt;&gt; scr_fp =3D [(&#=
39;11001138433007&#39;, &#39;1&#39;, 1),(&#39;11001138433007&#39;, &#39;2&#=
39;, 0)]<br>&gt;&gt;&gt; item_param, user_param =3D irt(scr_fp)<br>2018-09-=
21 16:38:48 INFO: start loading data<br>start loading data<br>*************=
************* [&#39;11001138433007&#39;, &#39;11001138433007&#39;] [&#39;1&=
#39;, &#39;2&#39;] [1, 0]<br>2018-09-21 16:38:48 INFO: data loaded<br>data =
loaded<br>100%|=E2=96=88=E2=96=88=E2=96=88=E2=96=88=E2=96=88=E2=96=88=E2=96=
=88=E2=96=88=E2=96=88=E2=96=88=E2=96=88=E2=96=88=E2=96=88=E2=96=88=E2=96=88=
=E2=96=88=E2=96=88=E2=96=88=E2=96=88=E2=96=88=E2=96=88=E2=96=88=E2=96=88=E2=
=96=88=E2=96=88=E2=96=88=E2=96=88=E2=96=88=E2=96=88=E2=96=88=E2=96=88=E2=96=
=88=E2=96=88=E2=96=88=E2=96=88=E2=96=88=E2=96=88=E2=96=88=E2=96=88=E2=96=88=
=E2=96=88=E2=96=88=E2=96=88=E2=96=88=E2=96=88=E2=96=88=E2=96=88=E2=96=88=E2=
=96=88=E2=96=88=E2=96=88=E2=96=88=E2=96=88=E2=96=88=E2=96=88=E2=96=88=E2=96=
=88=E2=96=88=E2=96=88=E2=96=88=E2=96=88=E2=96=88=E2=96=88=E2=96=88=E2=96=88=
=E2=96=88=E2=96=88=E2=96=88=E2=96=88=E2=96=88=E2=96=88=E2=96=88=E2=96=88=E2=
=96=88=E2=96=88=E2=96=88=E2=96=88=E2=96=88=E2=96=88=E2=96=88=E2=96=88=E2=96=
=88=E2=96=88=E2=96=88=E2=96=88=E2=96=88=E2=96=88=E2=96=88=E2=96=88=E2=96=88=
=E2=96=88=E2=96=88=E2=96=88=E2=96=88=E2=96=88=E2=96=88=E2=96=88=E2=96=88=E2=
=96=88=E2=96=88=E2=96=88=E2=96=88=E2=96=88=E2=96=88=E2=96=88=E2=96=88=E2=96=
=88=E2=96=88=E2=96=88=E2=96=88=E2=96=88=E2=96=88=E2=96=88=E2=96=88=E2=96=88=
=E2=96=88=E2=96=88=E2=96=88=E2=96=88=E2=96=88=E2=96=88=E2=96=88=E2=96=88=E2=
=96=88=E2=96=88=E2=96=88=E2=96=88=E2=96=88=E2=96=88=E2=96=88=E2=96=88=E2=96=
=88=E2=96=88=E2=96=88=E2=96=88=E2=96=88=E2=96=88=E2=96=88=E2=96=88=E2=96=88=
=E2=96=88=E2=96=88=E2=96=88=E2=96=88=E2=96=88=E2=96=88=E2=96=88=E2=96=88=E2=
=96=88=E2=96=88=E2=96=88=E2=96=88=E2=96=88=E2=96=88=E2=96=88=E2=96=88=E2=96=
=88=E2=96=88=E2=96=88=E2=96=88=E2=96=88=E2=96=88=E2=96=88=E2=96=88=E2=96=88=
=E2=96=88=E2=96=88=E2=96=88| 1/1 [00:00&lt;00:00, 639.77it/s]<br>=C2=A0 0%|=
=C2=A0=C2=A0=C2=A0=C2=A0=C2=A0=C2=A0=C2=A0=C2=A0=C2=A0=C2=A0=C2=A0=C2=A0=C2=
=A0=C2=A0=C2=A0=C2=A0=C2=A0=C2=A0=C2=A0=C2=A0=C2=A0=C2=A0=C2=A0=C2=A0=C2=A0=
=C2=A0=C2=A0=C2=A0=C2=A0=C2=A0=C2=A0=C2=A0=C2=A0=C2=A0=C2=A0=C2=A0=C2=A0=C2=
=A0=C2=A0=C2=A0=C2=A0=C2=A0=C2=A0=C2=A0=C2=A0=C2=A0=C2=A0=C2=A0=C2=A0=C2=A0=
=C2=A0=C2=A0=C2=A0=C2=A0=C2=A0=C2=A0=C2=A0=C2=A0=C2=A0=C2=A0=C2=A0=C2=A0=C2=
=A0=C2=A0=C2=A0=C2=A0=C2=A0=C2=A0=C2=A0=C2=A0=C2=A0=C2=A0=C2=A0=C2=A0=C2=A0=
=C2=A0=C2=A0=C2=A0=C2=A0=C2=A0=C2=A0=C2=A0=C2=A0=C2=A0=C2=A0=C2=A0=C2=A0=C2=
=A0=C2=A0=C2=A0=C2=A0=C2=A0=C2=A0=C2=A0=C2=A0=C2=A0=C2=A0=C2=A0=C2=A0=C2=A0=
=C2=A0=C2=A0=C2=A0=C2=A0=C2=A0=C2=A0=C2=A0=C2=A0=C2=A0=C2=A0=C2=A0=C2=A0=C2=
=A0=C2=A0=C2=A0=C2=A0=C2=A0=C2=A0=C2=A0=C2=A0=C2=A0=C2=A0=C2=A0=C2=A0=C2=A0=
=C2=A0=C2=A0=C2=A0=C2=A0=C2=A0=C2=A0=C2=A0=C2=A0=C2=A0=C2=A0=C2=A0=C2=A0=C2=
=A0=C2=A0=C2=A0=C2=A0=C2=A0=C2=A0=C2=A0=C2=A0=C2=A0=C2=A0=C2=A0=C2=A0=C2=A0=
=C2=A0=C2=A0=C2=A0=C2=A0=C2=A0=C2=A0=C2=A0=C2=A0=C2=A0=C2=A0=C2=A0=C2=A0=C2=
=A0=C2=A0=C2=A0=C2=A0=C2=A0=C2=A0=C2=A0=C2=A0=C2=A0=C2=A0=C2=A0=C2=A0=C2=A0=
=C2=A0 | 0/2 [00:00&lt;?, ?it/s]6666666666666666666666666666666666666CHAMAD=
AGET_MAP 0<br>TTTTTTTTTTTTTTTTTTTTTTTTTTTTTTGET_MAP3 [&#39;1&#39;, &#39;0&#=
39;]<br><br>--- Logging error ---<br>Traceback (most recent call last):<br>=
=C2=A0 File &quot;/home/graciela/descomplica/pyirt/pyirt/pyirt/solver/model=
.py&quot;, line 368, in update<br>=C2=A0=C2=A0=C2=A0 map_user_idx_vec =3D s=
elf.dao.get_map(item_idx, [&#39;1&#39;, &#39;0&#39;])<br>=C2=A0 File &quot;=
/home/graciela/descomplica/pyirt/pyirt/pyirt/dao.py&quot;, line 152, in get=
_map<br>=C2=A0=C2=A0=C2=A0 return [self.database.item2user_map[str(ans_key)=
][item_idx] for ans_key in ans_key_list]<br>=C2=A0 File &quot;/home/graciel=
a/descomplica/pyirt/pyirt/pyirt/dao.py&quot;, line 152, in &lt;listcomp&gt;=
<br>=C2=A0=C2=A0=C2=A0 return [self.database.item2user_map[str(ans_key)][it=
em_idx] for ans_key in ans_key_list]<br>KeyError: 0<br><br>During handling =
of the above exception, another exception occurred:<br><br>Traceback (most =
recent call last):<br>=C2=A0 File &quot;/usr/lib/python3.6/logging/__init__=
.py&quot;, line 993, in emit<br>=C2=A0=C2=A0=C2=A0 msg =3D self.format(reco=
rd)<br>=C2=A0 File &quot;/usr/lib/python3.6/logging/__init__.py&quot;, line=
 839, in format<br>=C2=A0=C2=A0=C2=A0 return fmt.format(record)<br>=C2=A0 F=
ile &quot;/usr/lib/python3.6/logging/__init__.py&quot;, line 576, in format=
<br>=C2=A0=C2=A0=C2=A0 record.message =3D record.getMessage()<br>=C2=A0 Fil=
e &quot;/usr/lib/python3.6/logging/__init__.py&quot;, line 338, in getMessa=
ge<br>=C2=A0=C2=A0=C2=A0 msg =3D msg % self.args<br>TypeError: not all argu=
ments converted during string formatting<br>Call stack:<br>=C2=A0 File &quo=
t;&lt;stdin&gt;&quot;, line 1, in &lt;module&gt;<br>=C2=A0 File &quot;/home=
/graciela/descomplica/pyirt/pyirt/pyirt/_pyirt.py&quot;, line 46, in irt<br=
>=C2=A0=C2=A0=C2=A0 mod.solve_EM()<br>=C2=A0 File &quot;/home/graciela/desc=
omplica/pyirt/pyirt/pyirt/solver/model.py&quot;, line 101, in solve_EM<br>=
=C2=A0=C2=A0=C2=A0 self._exp_step()<br>=C2=A0 File &quot;/home/graciela/des=
complica/pyirt/pyirt/pyirt/solver/model.py&quot;, line 161, in _exp_step<br=
>=C2=A0=C2=A0=C2=A0 self.__get_expect_count()<br>=C2=A0 File &quot;/home/gr=
aciela/descomplica/pyirt/pyirt/pyirt/solver/model.py&quot;, line 395, in __=
get_expect_count<br>=C2=A0=C2=A0=C2=A0 procs =3D procs_operator(procs, 7200=
, 0.1)<br>=C2=A0 File &quot;/home/graciela/descomplica/pyirt/pyirt/pyirt/so=
lver/model.py&quot;, line 27, in procs_operator<br>=C2=A0=C2=A0=C2=A0 p.sta=
rt()<br>=C2=A0 File &quot;/usr/lib/python3.6/multiprocessing/process.py&quo=
t;, line 105, in start<br>=C2=A0=C2=A0=C2=A0 self._popen =3D self._Popen(se=
lf)<br>=C2=A0 File &quot;/usr/lib/python3.6/multiprocessing/context.py&quot=
;, line 223, in _Popen<br>=C2=A0=C2=A0=C2=A0 return _default_context.get_co=
ntext().Process._Popen(process_obj)<br>=C2=A0 File &quot;/usr/lib/python3.6=
/multiprocessing/context.py&quot;, line 277, in _Popen<br>=C2=A0=C2=A0=C2=
=A0 return Popen(process_obj)<br>=C2=A0 File &quot;/usr/lib/python3.6/multi=
processing/popen_fork.py&quot;, line 19, in __init__<br>=C2=A0=C2=A0=C2=A0 =
self._launch(process_obj)<br>=C2=A0 File &quot;/usr/lib/python3.6/multiproc=
essing/popen_fork.py&quot;, line 73, in _launch<br>=C2=A0=C2=A0=C2=A0 code =
=3D process_obj._bootstrap()<br>=C2=A0 File &quot;/usr/lib/python3.6/multip=
rocessing/process.py&quot;, line 258, in _bootstrap<br>=C2=A0=C2=A0=C2=A0 s=
elf.run()<br>=C2=A0 File &quot;/usr/lib/python3.6/multiprocessing/process.p=
y&quot;, line 93, in run<br>=C2=A0=C2=A0=C2=A0 self._target(*self._args, **=
self._kwargs)<br>=C2=A0 File &quot;/home/graciela/descomplica/pyirt/pyirt/p=
yirt/solver/model.py&quot;, line 374, in update<br>=C2=A0=C2=A0=C2=A0 self.=
logger.critical(&quot;Unexpected error:&quot;, str(e))<br>Message: &#39;Une=
xpected error:&#39;<br>Arguments: (&#39;0&#39;,)<br>--- Logging error ---<b=
r>Traceback (most recent call last):<br>=C2=A0 File &quot;/home/graciela/de=
scomplica/pyirt/pyirt/pyirt/solver/model.py&quot;, line 368, in update<br>=
=C2=A0=C2=A0=C2=A0 map_user_idx_vec =3D self.dao.get_map(item_idx, [&#39;1&=
#39;, &#39;0&#39;])<br>=C2=A0 File &quot;/home/graciela/descomplica/pyirt/p=
yirt/pyirt/dao.py&quot;, line 152, in get_map<br>=C2=A0=C2=A0=C2=A0 return =
[self.database.item2user_map[str(ans_key)][item_idx] for ans_key in ans_key=
_list]<br>=C2=A0 File &quot;/home/graciela/descomplica/pyirt/pyirt/pyirt/da=
o.py&quot;, line 152, in &lt;listcomp&gt;<br>=C2=A0=C2=A0=C2=A0 return [sel=
f.database.item2user_map[str(ans_key)][item_idx] for ans_key in ans_key_lis=
t]<br>KeyError: 0<br><br>During handling of the above exception, another ex=
ception occurred:<br><br>Traceback (most recent call last):<br>=C2=A0 File =
&quot;/usr/lib/python3.6/logging/__init__.py&quot;, line 993, in emit<br>=
=C2=A0=C2=A0=C2=A0 msg =3D self.format(record)<br>=C2=A0 File &quot;/usr/li=
b/python3.6/logging/__init__.py&quot;, line 839, in format<br>=C2=A0=C2=A0=
=C2=A0 return fmt.format(record)<br>=C2=A0 File &quot;/usr/lib/python3.6/lo=
gging/__init__.py&quot;, line 576, in format<br>=C2=A0=C2=A0=C2=A0 record.m=
essage =3D record.getMessage()<br>=C2=A0 File &quot;/usr/lib/python3.6/logg=
ing/__init__.py&quot;, line 338, in getMessage<br>=C2=A0=C2=A0=C2=A0 msg =
=3D msg % self.args<br>TypeError: not all arguments converted during string=
 formatting<br>Call stack:<br>=C2=A0 File &quot;&lt;stdin&gt;&quot;, line 1=
, in &lt;module&gt;<br>=C2=A0 File &quot;/home/graciela/descomplica/pyirt/p=
yirt/pyirt/_pyirt.py&quot;, line 46, in irt<br>=C2=A0=C2=A0=C2=A0 mod.solve=
_EM()<br>=C2=A0 File &quot;/home/graciela/descomplica/pyirt/pyirt/pyirt/sol=
ver/model.py&quot;, line 101, in solve_EM<br>=C2=A0=C2=A0=C2=A0 self._exp_s=
tep()<br>=C2=A0 File &quot;/home/graciela/descomplica/pyirt/pyirt/pyirt/sol=
ver/model.py&quot;, line 161, in _exp_step<br>=C2=A0=C2=A0=C2=A0 self.__get=
_expect_count()<br>=C2=A0 File &quot;/home/graciela/descomplica/pyirt/pyirt=
/pyirt/solver/model.py&quot;, line 395, in __get_expect_count<br>=C2=A0=C2=
=A0=C2=A0 procs =3D procs_operator(procs, 7200, 0.1)<br>=C2=A0 File &quot;/=
home/graciela/descomplica/pyirt/pyirt/pyirt/solver/model.py&quot;, line 27,=
 in procs_operator<br>=C2=A0=C2=A0=C2=A0 p.start()<br>=C2=A0 File &quot;/us=
r/lib/python3.6/multiprocessing/process.py&quot;, line 105, in start<br>=C2=
=A0=C2=A0=C2=A0 self._popen =3D self._Popen(self)<br>=C2=A0 File &quot;/usr=
/lib/python3.6/multiprocessing/context.py&quot;, line 223, in _Popen<br>=C2=
=A0=C2=A0=C2=A0 return _default_context.get_context().Process._Popen(proces=
s_obj)<br>=C2=A0 File &quot;/usr/lib/python3.6/multiprocessing/context.py&q=
uot;, line 277, in _Popen<br>=C2=A0=C2=A0=C2=A0 return Popen(process_obj)<b=
r>=C2=A0 File &quot;/usr/lib/python3.6/multiprocessing/popen_fork.py&quot;,=
 line 19, in __init__<br>=C2=A0=C2=A0=C2=A0 self._launch(process_obj)<br>=
=C2=A0 File &quot;/usr/lib/python3.6/multiprocessing/popen_fork.py&quot;, l=
ine 73, in _launch<br>=C2=A0=C2=A0=C2=A0 code =3D process_obj._bootstrap()<=
br>=C2=A0 File &quot;/usr/lib/python3.6/multiprocessing/process.py&quot;, l=
ine 258, in _bootstrap<br>=C2=A0=C2=A0=C2=A0 self.run()<br>=C2=A0 File &quo=
t;/usr/lib/python3.6/multiprocessing/process.py&quot;, line 93, in run<br>=
=C2=A0=C2=A0=C2=A0 self._target(*self._args, **self._kwargs)<br>=C2=A0 File=
 &quot;/home/graciela/descomplica/pyirt/pyirt/pyirt/solver/model.py&quot;, =
line 374, in update<br>=C2=A0=C2=A0=C2=A0 self.logger.critical(&quot;Unexpe=
cted error:&quot;, str(e))<br>Message: &#39;Unexpected error:&#39;<br>Argum=
ents: (&#39;0&#39;,)<br>Process Process-4:<br>Traceback (most recent call l=
ast):<br>=C2=A0 File &quot;/usr/lib/python3.6/multiprocessing/process.py&qu=
ot;, line 258, in _bootstrap<br>=C2=A0=C2=A0=C2=A0 self.run()<br>=C2=A0 Fil=
e &quot;/usr/lib/python3.6/multiprocessing/process.py&quot;, line 93, in ru=
n<br>=C2=A0=C2=A0=C2=A0 self._target(*self._args, **self._kwargs)<br>=C2=A0=
 File &quot;/home/graciela/descomplica/pyirt/pyirt/pyirt/solver/model.py&qu=
ot;, line 375, in update<br>=C2=A0=C2=A0=C2=A0 raise e<br>=C2=A0 File &quot=
;/home/graciela/descomplica/pyirt/pyirt/pyirt/solver/model.py&quot;, line 3=
68, in update<br>=C2=A0=C2=A0=C2=A0 map_user_idx_vec =3D self.dao.get_map(i=
tem_idx, [&#39;1&#39;, &#39;0&#39;])<br>=C2=A0 File &quot;/home/graciela/de=
scomplica/pyirt/pyirt/pyirt/dao.py&quot;, line 152, in get_map<br>=C2=A0=C2=
=A0=C2=A0 return [self.database.item2user_map[str(ans_key)][item_idx] for a=
ns_key in ans_key_list]<br>=C2=A0 File &quot;/home/graciela/descomplica/pyi=
rt/pyirt/pyirt/dao.py&quot;, line 152, in &lt;listcomp&gt;<br>=C2=A0=C2=A0=
=C2=A0 return [self.database.item2user_map[str(ans_key)][item_idx] for ans_=
key in ans_key_list]<br>KeyError: 0<br>Traceback (most recent call last):<b=
r>=C2=A0 File &quot;&lt;stdin&gt;&quot;, line 1, in &lt;module&gt;<br>=C2=
=A0 File &quot;/home/graciela/descomplica/pyirt/pyirt/pyirt/_pyirt.py&quot;=
, line 46, in irt<br>=C2=A0=C2=A0=C2=A0 mod.solve_EM()<br>=C2=A0 File &quot=
;/home/graciela/descomplica/pyirt/pyirt/pyirt/solver/model.py&quot;, line 1=
01, in solve_EM<br>=C2=A0=C2=A0=C2=A0 self._exp_step()<br>=C2=A0 File &quot=
;/home/graciela/descomplica/pyirt/pyirt/pyirt/solver/model.py&quot;, line 1=
61, in _exp_step<br>=C2=A0=C2=A0=C2=A0 self.__get_expect_count()<br>=C2=A0 =
File &quot;/home/graciela/descomplica/pyirt/pyirt/pyirt/solver/model.py&quo=
t;, line 400, in __get_expect_count<br>=C2=A0=C2=A0=C2=A0 self.item_expecte=
d_right_by_theta[:, item_idx] =3D procs_repo[item_idx][1]<br>=C2=A0 File &q=
uot;&lt;string&gt;&quot;, line 2, in __getitem__<br>=C2=A0 File &quot;/usr/=
lib/python3.6/multiprocessing/managers.py&quot;, line 772, in _callmethod<b=
r>=C2=A0=C2=A0=C2=A0 raise convert_to_error(kind, result)<br>KeyError: 0<br=
><br></div></div>

<p></p>

-- <br />
-- <br />
------------------------------------<br />
Grupo Python-Brasil<br />
<a href=3D"https://wiki.python.org.br/AntesDePerguntar">https://wiki.python=
.org.br/AntesDePerguntar</a><br />
&nbsp;<br />
&lt;*&gt; Para visitar o site do grupo na web, acesse:<br />
    <a href=3D"http://groups.google.com/group/python-brasil">http://groups.=
google.com/group/python-brasil</a><br />
&nbsp;<br />
&lt;*&gt; Para sair deste grupo, envie um e-mail para:<br />
    python-brasil+unsubscribe@googlegroups.com<br />
--- <br />
Voc=C3=AA recebeu essa mensagem porque est=C3=A1 inscrito no grupo &quot;Py=
thon Brasil&quot; dos Grupos do Google.<br />
Para cancelar inscri=C3=A7=C3=A3o nesse grupo e parar de receber e-mails de=
le, envie um e-mail para <a href=3D"mailto:python-brasil+unsubscribe@google=
groups.com">python-brasil+unsubscribe@googlegroups.com</a>.<br />
Para postar nesse grupo, envie um e-mail para <a href=3D"mailto:python-bras=
il@googlegroups.com">python-brasil@googlegroups.com</a>.<br />
Para ver essa discuss=C3=A3o na Web, acesse <a href=3D"https://groups.googl=
e.com/d/msgid/python-brasil/b2711e28-8529-4bb6-b3a9-79cd94043995%40googlegr=
oups.com?utm_medium=3Demail&utm_source=3Dfooter">https://groups.google.com/=
d/msgid/python-brasil/b2711e28-8529-4bb6-b3a9-79cd94043995%40googlegroups.c=
om</a>.<br />
Para mais op=C3=A7=C3=B5es, acesse <a href=3D"https://groups.google.com/d/o=
ptout">https://groups.google.com/d/optout</a>.<br />

------=_Part_1093_1766374657.1537560540292--

------=_Part_1092_1872254557.1537560540291--
