Delivered-To: meduardo.r@gmail.com
Received: by 2002:a5d:560c:0:0:0:0:0 with SMTP id l12-v6csp854545wrv;
        Wed, 26 Sep 2018 09:29:57 -0700 (PDT)
X-Received: by 2002:a25:1a85:: with SMTP id a127-v6mr3592483yba.507.1537979397016;
        Wed, 26 Sep 2018 09:29:57 -0700 (PDT)
ARC-Seal: i=1; a=rsa-sha256; t=1537979396; cv=none;
        d=google.com; s=arc-20160816;
        b=ZlfYdRCi4I/lJ9Hui+qYMzIFZkQuQhzxXdkJKjFG4MAUeet0moXysg4MjBrVUuwtkr
         POEzkLOWlByotxsZMj/CXFCcDYQ8nMY8X7E5rDDiq0YeQ6gcGac+WV79yULiuDjIawd4
         MH/Vn7wuRMolPFmWN/Hpb3EIrSiiuxA4LU3WF2ZnnPEoyC7yeZazWEnhFiRpOtFFMDu/
         pAfvD7dAIjVZUYg75PhjBkWYcG7kqRocYQtTXLanIj9ZjofCwtKh3gsIZwZ4BOFRmBKD
         T0sKHhjPKefncTBUD40Us1BsZCw30WQlH5g0LoGd64irOCS2mUK8EiZ8tD/XnXIgnVr6
         BNwA==
ARC-Message-Signature: i=1; a=rsa-sha256; c=relaxed/relaxed; d=google.com; s=arc-20160816;
        h=list-unsubscribe:list-subscribe:list-archive:list-help:list-post
         :list-id:mailing-list:precedence:reply-to:mime-version:subject
         :message-id:to:from:date:sender:dkim-signature;
        bh=0htVwdrO49xwLYpepyYEax+HA+N0MBVlpyfCkjsss1s=;
        b=vq0Y+SoeQr4tZf+9V+X6JwdXbf8OlrTYzsgiBMlDg1OTgILtzTgGqgQ0aMoWCEPx/0
         kYvfkSm2eUh6twe6BM07oj4OaTQYqvlq5AvZC/9x5yq7FSizjJtjDz7K3tBiruvAEchR
         iJKlajJPW8458vMAKIMNdjRWK5Esbd/DP6CHZwab7RZIWAZ8UOVHj/66qkG7nXsAB95V
         4RY96U4ds3yjYFwYylEe/NJwGCvEeufFxUmEn9sZPqHis5lWqhGFLVlmEeF1tSL/ieHt
         Mu+W/Kc8E47t+63hl2CwbEK2hJfeL1WDHNmS6oY/4kJUEXCmm61/f5oH5BzelDuy+bvi
         PwJA==
ARC-Authentication-Results: i=1; mx.google.com;
       dkim=pass header.i=@googlegroups.com header.s=20161025 header.b=ZHwkEwQY;
       spf=pass (google.com: domain of python-brasil+bncbd26rvfzyairb7phv3oqkgqe5aba6gi@googlegroups.com designates 209.85.220.55 as permitted sender) smtp.mailfrom=python-brasil+bncBD26RVFZYAIRB7PHV3OQKGQE5ABA6GI@googlegroups.com;
       dmarc=fail (p=NONE sp=QUARANTINE dis=NONE) header.from=gmail.com
Return-Path: <python-brasil+bncBD26RVFZYAIRB7PHV3OQKGQE5ABA6GI@googlegroups.com>
Received: from mail-sor-f55.google.com (mail-sor-f55.google.com. [209.85.220.55])
        by mx.google.com with SMTPS id c13-v6sor707125ybn.51.2018.09.26.09.29.56
        (Google Transport Security);
        Wed, 26 Sep 2018 09:29:56 -0700 (PDT)
Received-SPF: pass (google.com: domain of python-brasil+bncbd26rvfzyairb7phv3oqkgqe5aba6gi@googlegroups.com designates 209.85.220.55 as permitted sender) client-ip=209.85.220.55;
Authentication-Results: mx.google.com;
       dkim=pass header.i=@googlegroups.com header.s=20161025 header.b=ZHwkEwQY;
       spf=pass (google.com: domain of python-brasil+bncbd26rvfzyairb7phv3oqkgqe5aba6gi@googlegroups.com designates 209.85.220.55 as permitted sender) smtp.mailfrom=python-brasil+bncBD26RVFZYAIRB7PHV3OQKGQE5ABA6GI@googlegroups.com;
       dmarc=fail (p=NONE sp=QUARANTINE dis=NONE) header.from=gmail.com
DKIM-Signature: v=1; a=rsa-sha256; c=relaxed/relaxed;
        d=googlegroups.com; s=20161025;
        h=sender:date:from:to:message-id:subject:mime-version
         :x-original-sender:reply-to:precedence:mailing-list:list-id
         :list-post:list-help:list-archive:list-subscribe:list-unsubscribe;
        bh=0htVwdrO49xwLYpepyYEax+HA+N0MBVlpyfCkjsss1s=;
        b=ZHwkEwQYdCBtoar+PScWiBkhNrK7N4fK7zQ9QpLezOgQpbIBkCMfkxQl5zNN048Oqc
         5374FpIJiteIMtkD3nOuM8PWb7essTUtK/IhkUFpY+rciDJW4k/QtGf/xyS50zyIOMC1
         JuDljX+advjT1fL6wUtndRAI4uaeQV1FXBfrIfqc3WOSI8wh6JKvCsBUu/9VKXeZDFwP
         pBjkUMGhlRlUgWb/RaZf6PY4efaTTS+8g2EOEE1nKLts0G4WpRjaSDcnRMtLxfuYQlqU
         3+/DPpitM8gU3doIRkD6Z4HklTagDLpQixrG94SAKhyIHdc1QI78QrEiJTMmtIMJRpYs
         NvLA==
X-Google-DKIM-Signature: v=1; a=rsa-sha256; c=relaxed/relaxed;
        d=1e100.net; s=20161025;
        h=sender:x-gm-message-state:date:from:to:message-id:subject
         :mime-version:x-original-sender:reply-to:precedence:mailing-list
         :list-id:list-post:list-help:list-archive:list-subscribe
         :list-unsubscribe;
        bh=0htVwdrO49xwLYpepyYEax+HA+N0MBVlpyfCkjsss1s=;
        b=iV3EHyGXXafhEyVlKCjeAr3A8kzCeug3QXPYr4EOYeP/Uz2L7KFqbP+J5Y09y8fAAc
         vCAyXlr1IwvGjSkeAj4Tk3+BW6hvGkFyDcqxkwd+DZBDjRTD7KkWtD5uzBWajlikAvFE
         eHfq4Re2HQCpgrHDI+PU9qv+eY9h0V3cYVDYjnVR+MQxqumFD3or5aQh+n3TpOirUSL3
         rBiyFgikYo4XINbuDSy8bX27s/8JxI0SqQQYgjaOQqCaKwUXnzW0N0HUAaV/+YNGj74X
         1zcHTFniOtI18J28RAT47ud3pJH9mahj5x0dvk36Q1tn6VUpID9JAqjAqnTUecWjNHKx
         YZMA==
Sender: python-brasil@googlegroups.com
X-Gm-Message-State: ABuFfoj77m2BZMqnLLOVXVCV5AOqvvGIKNLYwilFy85552cRTLmo2m7o
	UFT+MTHvKEun/sz4CbVajtk=
X-Google-Smtp-Source: ACcGV62l+462q3o6zI8SHoqRWJ442odaWJ4uINN7HYhr1pmnddgAf2oIwGKf7hlK+52FH06yZVbCuw==
X-Received: by 2002:a5b:b84:: with SMTP id l4-v6mr82245ybq.0.1537979396403;
        Wed, 26 Sep 2018 09:29:56 -0700 (PDT)
X-BeenThere: python-brasil@googlegroups.com
Received: by 2002:a5b:3c9:: with SMTP id t9-v6ls294116ybp.22.gmail; Wed, 26
 Sep 2018 09:29:49 -0700 (PDT)
X-Received: by 2002:a25:ef05:: with SMTP id g5-v6mr450560ybd.78.1537979389653;
        Wed, 26 Sep 2018 09:29:49 -0700 (PDT)
Received: by 2002:a81:6cc6:0:0:0:0:0 with SMTP id h189-v6msywc;
        Fri, 21 Sep 2018 13:03:32 -0700 (PDT)
X-Received: by 2002:a0d:dfc1:: with SMTP id i184-v6mr56079ywe.4.1537560212572;
        Fri, 21 Sep 2018 13:03:32 -0700 (PDT)
Date: Fri, 21 Sep 2018 13:03:32 -0700 (PDT)
From: Graciela Oliveira <graciela.oliveira@gmail.com>
To: Python Brasil <python-brasil@googlegroups.com>
Message-Id: <f05b452f-ada9-4980-bc81-e938ed3c4a94@googlegroups.com>
Subject: [python-brasil] Biblioteca pyirt - Teoria da Resposta ao Item
MIME-Version: 1.0
Content-Type: multipart/mixed; 
	boundary="----=_Part_1026_185157175.1537560212376"
X-Original-Sender: graciela.oliveira@gmail.com
Reply-To: python-brasil@googlegroups.com
Precedence: list
Mailing-list: list python-brasil@googlegroups.com; contact python-brasil+owners@googlegroups.com
List-ID: <python-brasil.googlegroups.com>
X-Google-Group-Id: 976534909641
List-Post: <https://groups.google.com/group/python-brasil/post>, <mailto:python-brasil@googlegroups.com>
List-Help: <https://groups.google.com/support/>, <mailto:python-brasil+help@googlegroups.com>
List-Archive: <https://groups.google.com/group/python-brasil
List-Subscribe: <https://groups.google.com/group/python-brasil/subscribe>, <mailto:python-brasil+subscribe@googlegroups.com>
List-Unsubscribe: <mailto:googlegroups-manage+976534909641+unsubscribe@googlegroups.com>,
 <https://groups.google.com/group/python-brasil/subscribe>

------=_Part_1026_185157175.1537560212376
Content-Type: multipart/alternative; 
	boundary="----=_Part_1027_574696549.1537560212376"

------=_Part_1027_574696549.1537560212376
Content-Type: text/plain; charset="UTF-8"
Content-Transfer-Encoding: quoted-printable

Boa tarde,

Eu estou usando a biblioteca pyirt (https://github.com/17zuoye/pyirt) e=20
estou encontrando problemas ao tentar rodar o algoritmo.


Algu=C3=A9m j=C3=A1 teve contato com essa biblioteca e poderia me ajudar?


scr_fp =3D [('11001138433007', '1', 1),('11001138433007', '2', 0)]
>>> item_param, user_param =3D irt(scr_fp)
2018-09-21 16:38:48 INFO: start loading data
start loading data
************************** ['11001138433007', '11001138433007'] ['1', '2']=
=20
[1, 0]
2018-09-21 16:38:48 INFO: data loaded
data loaded
100%|=E2=96=88=E2=96=88=E2=96=88=E2=96=88=E2=96=88=E2=96=88=E2=96=88=E2=96=
=88=E2=96=88=E2=96=88=E2=96=88=E2=96=88=E2=96=88=E2=96=88=E2=96=88=E2=96=88=
=E2=96=88=E2=96=88=E2=96=88=E2=96=88=E2=96=88=E2=96=88=E2=96=88=E2=96=88=E2=
=96=88=E2=96=88=E2=96=88=E2=96=88=E2=96=88=E2=96=88=E2=96=88=E2=96=88=E2=96=
=88=E2=96=88=E2=96=88=E2=96=88=E2=96=88=E2=96=88=E2=96=88=E2=96=88=E2=96=88=
=E2=96=88=E2=96=88=E2=96=88=E2=96=88=E2=96=88=E2=96=88=E2=96=88=E2=96=88=E2=
=96=88=E2=96=88=E2=96=88=E2=96=88=E2=96=88=E2=96=88=E2=96=88=E2=96=88=E2=96=
=88=E2=96=88=E2=96=88=E2=96=88=E2=96=88=E2=96=88=E2=96=88=E2=96=88=E2=96=88=
=E2=96=88=E2=96=88=E2=96=88=E2=96=88=E2=96=88=E2=96=88=E2=96=88=E2=96=88=E2=
=96=88=E2=96=88=E2=96=88=E2=96=88=E2=96=88=E2=96=88=E2=96=88=E2=96=88=E2=96=
=88=E2=96=88=E2=96=88=E2=96=88=E2=96=88=E2=96=88=E2=96=88=E2=96=88=E2=96=88=
=E2=96=88=E2=96=88=E2=96=88=E2=96=88=E2=96=88=E2=96=88=E2=96=88=E2=96=88=E2=
=96=88=E2=96=88=E2=96=88=E2=96=88=E2=96=88=E2=96=88=E2=96=88=E2=96=88=E2=96=
=88=E2=96=88=E2=96=88=E2=96=88=E2=96=88=E2=96=88=E2=96=88=E2=96=88=E2=96=88=
=E2=96=88=E2=96=88=E2=96=88=E2=96=88=E2=96=88=E2=96=88=E2=96=88=E2=96=88=E2=
=96=88=E2=96=88=E2=96=88=E2=96=88=E2=96=88=E2=96=88=E2=96=88=E2=96=88=E2=96=
=88=E2=96=88=E2=96=88=E2=96=88=E2=96=88=E2=96=88=E2=96=88=E2=96=88=E2=96=88=
=E2=96=88=E2=96=88=E2=96=88=E2=96=88=E2=96=88=E2=96=88=E2=96=88=E2=96=88=E2=
=96=88=E2=96=88=E2=96=88=E2=96=88=E2=96=88=E2=96=88=E2=96=88=E2=96=88=E2=96=
=88=E2=96=88=E2=96=88=E2=96=88=E2=96=88=E2=96=88=E2=96=88=E2=96=88=E2=96=88=
=E2=96=88=E2=96=88|=20
1/1 [00:00<00:00, 639.77it/s]
 =20
0%|                                                                        =
                                                                           =
                             =20
| 0/2 [00:00<?, ?it/s]6666666666666666666666666666666666666CHAMADAGET_MAP 0
TTTTTTTTTTTTTTTTTTTTTTTTTTTTTTGET_MAP3 ['1', '0']

--- Logging error ---
Traceback (most recent call last):
  File "/home/graciela/descomplica/pyirt/pyirt/pyirt/solver/model.py", line=
=20
368, in update
    map_user_idx_vec =3D self.dao.get_map(item_idx, ['1', '0'])
  File "/home/graciela/descomplica/pyirt/pyirt/pyirt/dao.py", line 152, in=
=20
get_map
    return [self.database.item2user_map[str(ans_key)][item_idx] for ans_key=
=20
in ans_key_list]
  File "/home/graciela/descomplica/pyirt/pyirt/pyirt/dao.py", line 152, in=
=20
<listcomp>
    return [self.database.item2user_map[str(ans_key)][item_idx] for ans_key=
=20
in ans_key_list]
KeyError: 0

During handling of the above exception, another exception occurred:

Traceback (most recent call last):
  File "/usr/lib/python3.6/logging/__init__.py", line 993, in emit
    msg =3D self.format(record)
  File "/usr/lib/python3.6/logging/__init__.py", line 839, in format
    return fmt.format(record)
  File "/usr/lib/python3.6/logging/__init__.py", line 576, in format
    record.message =3D record.getMessage()
  File "/usr/lib/python3.6/logging/__init__.py", line 338, in getMessage
    msg =3D msg % self.args
TypeError: not all arguments converted during string formatting
Call stack:
  File "<stdin>", line 1, in <module>
  File "/home/graciela/descomplica/pyirt/pyirt/pyirt/_pyirt.py", line 46,=
=20
in irt
    mod.solve_EM()
  File "/home/graciela/descomplica/pyirt/pyirt/pyirt/solver/model.py", line=
=20
101, in solve_EM
    self._exp_step()
  File "/home/graciela/descomplica/pyirt/pyirt/pyirt/solver/model.py", line=
=20
161, in _exp_step
    self.__get_expect_count()
  File "/home/graciela/descomplica/pyirt/pyirt/pyirt/solver/model.py", line=
=20
395, in __get_expect_count
    procs =3D procs_operator(procs, 7200, 0.1)
  File "/home/graciela/descomplica/pyirt/pyirt/pyirt/solver/model.py", line=
=20
27, in procs_operator
    p.start()
  File "/usr/lib/python3.6/multiprocessing/process.py", line 105, in start
    self._popen =3D self._Popen(self)
  File "/usr/lib/python3.6/multiprocessing/context.py", line 223, in _Popen
    return _default_context.get_context().Process._Popen(process_obj)
  File "/usr/lib/python3.6/multiprocessing/context.py", line 277, in _Popen
    return Popen(process_obj)
  File "/usr/lib/python3.6/multiprocessing/popen_fork.py", line 19, in=20
__init__
    self._launch(process_obj)
  File "/usr/lib/python3.6/multiprocessing/popen_fork.py", line 73, in=20
_launch
    code =3D process_obj._bootstrap()
  File "/usr/lib/python3.6/multiprocessing/process.py", line 258, in=20
_bootstrap
    self.run()
  File "/usr/lib/python3.6/multiprocessing/process.py", line 93, in run
    self._target(*self._args, **self._kwargs)
  File "/home/graciela/descomplica/pyirt/pyirt/pyirt/solver/model.py", line=
=20
374, in update
    self.logger.critical("Unexpected error:", str(e))
Message: 'Unexpected error:'
Arguments: ('0',)
--- Logging error ---
Traceback (most recent call last):
  File "/home/graciela/descomplica/pyirt/pyirt/pyirt/solver/model.py", line=
=20
368, in update
    map_user_idx_vec =3D self.dao.get_map(item_idx, ['1', '0'])
  File "/home/graciela/descomplica/pyirt/pyirt/pyirt/dao.py", line 152, in=
=20
get_map
    return [self.database.item2user_map[str(ans_key)][item_idx] for ans_key=
=20
in ans_key_list]
  File "/home/graciela/descomplica/pyirt/pyirt/pyirt/dao.py", line 152, in=
=20
<listcomp>
    return [self.database.item2user_map[str(ans_key)][item_idx] for ans_key=
=20
in ans_key_list]
KeyError: 0

During handling of the above exception, another exception occurred:

Traceback (most recent call last):
  File "/usr/lib/python3.6/logging/__init__.py", line 993, in emit
    msg =3D self.format(record)
  File "/usr/lib/python3.6/logging/__init__.py", line 839, in format
    return fmt.format(record)
  File "/usr/lib/python3.6/logging/__init__.py", line 576, in format
    record.message =3D record.getMessage()
  File "/usr/lib/python3.6/logging/__init__.py", line 338, in getMessage
    msg =3D msg % self.args
TypeError: not all arguments converted during string formatting
Call stack:
  File "<stdin>", line 1, in <module>
  File "/home/graciela/descomplica/pyirt/pyirt/pyirt/_pyirt.py", line 46,=
=20
in irt
    mod.solve_EM()
  File "/home/graciela/descomplica/pyirt/pyirt/pyirt/solver/model.py", line=
=20
101, in solve_EM
    self._exp_step()
  File "/home/graciela/descomplica/pyirt/pyirt/pyirt/solver/model.py", line=
=20
161, in _exp_step
    self.__get_expect_count()
  File "/home/graciela/descomplica/pyirt/pyirt/pyirt/solver/model.py", line=
=20
395, in __get_expect_count
    procs =3D procs_operator(procs, 7200, 0.1)
  File "/home/graciela/descomplica/pyirt/pyirt/pyirt/solver/model.py", line=
=20
27, in procs_operator
    p.start()
  File "/usr/lib/python3.6/multiprocessing/process.py", line 105, in start
    self._popen =3D self._Popen(self)
  File "/usr/lib/python3.6/multiprocessing/context.py", line 223, in _Popen
    return _default_context.get_context().Process._Popen(process_obj)
  File "/usr/lib/python3.6/multiprocessing/context.py", line 277, in _Popen
    return Popen(process_obj)
  File "/usr/lib/python3.6/multiprocessing/popen_fork.py", line 19, in=20
__init__
    self._launch(process_obj)
  File "/usr/lib/python3.6/multiprocessing/popen_fork.py", line 73, in=20
_launch
    code =3D process_obj._bootstrap()
  File "/usr/lib/python3.6/multiprocessing/process.py", line 258, in=20
_bootstrap
    self.run()
  File "/usr/lib/python3.6/multiprocessing/process.py", line 93, in run
    self._target(*self._args, **self._kwargs)
  File "/home/graciela/descomplica/pyirt/pyirt/pyirt/solver/model.py", line=
=20
374, in update
    self.logger.critical("Unexpected error:", str(e))
Message: 'Unexpected error:'
Arguments: ('0',)
Process Process-4:
Traceback (most recent call last):
  File "/usr/lib/python3.6/multiprocessing/process.py", line 258, in=20
_bootstrap
    self.run()
  File "/usr/lib/python3.6/multiprocessing/process.py", line 93, in run
    self._target(*self._args, **self._kwargs)
  File "/home/graciela/descomplica/pyirt/pyirt/pyirt/solver/model.py", line=
=20
375, in update
    raise e
  File "/home/graciela/descomplica/pyirt/pyirt/pyirt/solver/model.py", line=
=20
368, in update
    map_user_idx_vec =3D self.dao.get_map(item_idx, ['1', '0'])
  File "/home/graciela/descomplica/pyirt/pyirt/pyirt/dao.py", line 152, in=
=20
get_map
    return [self.database.item2user_map[str(ans_key)][item_idx] for ans_key=
=20
in ans_key_list]
  File "/home/graciela/descomplica/pyirt/pyirt/pyirt/dao.py", line 152, in=
=20
<listcomp>
    return [self.database.item2user_map[str(ans_key)][item_idx] for ans_key=
=20
in ans_key_list]
KeyError: 0
Traceback (most recent call last):
  File "<stdin>", line 1, in <module>
  File "/home/graciela/descomplica/pyirt/pyirt/pyirt/_pyirt.py", line 46,=
=20
in irt
    mod.solve_EM()
  File "/home/graciela/descomplica/pyirt/pyirt/pyirt/solver/model.py", line=
=20
101, in solve_EM
    self._exp_step()
  File "/home/graciela/descomplica/pyirt/pyirt/pyirt/solver/model.py", line=
=20
161, in _exp_step
    self.__get_expect_count()
  File "/home/graciela/descomplica/pyirt/pyirt/pyirt/solver/model.py", line=
=20
400, in __get_expect_count
    self.item_expected_right_by_theta[:, item_idx] =3D procs_repo[item_idx]=
[1]
  File "<string>", line 2, in __getitem__
  File "/usr/lib/python3.6/multiprocessing/managers.py", line 772, in=20
_callmethod
    raise convert_to_error(kind, result)
KeyError: 0

--=20
--=20
------------------------------------
Grupo Python-Brasil
https://wiki.python.org.br/AntesDePerguntar

<*> Para visitar o site do grupo na web, acesse:
    http://groups.google.com/group/python-brasil

<*> Para sair deste grupo, envie um e-mail para:
    python-brasil+unsubscribe@googlegroups.com
---=20
Voc=C3=AA est=C3=A1 recebendo esta mensagem porque se inscreveu no grupo "P=
ython Brasil" dos Grupos do Google.
Para cancelar inscri=C3=A7=C3=A3o nesse grupo e parar de receber e-mails de=
le, envie um e-mail para python-brasil+unsubscribe@googlegroups.com.
Para postar neste grupo, envie um e-mail para python-brasil@googlegroups.co=
m.
Para ver esta discuss=C3=A3o na web, acesse https://groups.google.com/d/msg=
id/python-brasil/f05b452f-ada9-4980-bc81-e938ed3c4a94%40googlegroups.com.
Para obter mais op=C3=A7=C3=B5es, acesse https://groups.google.com/d/optout=
.

------=_Part_1027_574696549.1537560212376
Content-Type: text/html; charset="UTF-8"
Content-Transfer-Encoding: quoted-printable

<div dir=3D"ltr"><div>Boa tarde,</div><div><br></div><div>Eu estou usando a=
 biblioteca pyirt (https://github.com/17zuoye/pyirt) e estou encontrando pr=
oblemas ao tentar rodar o algoritmo.<br><br><br>Algu=C3=A9m j=C3=A1 teve co=
ntato com essa biblioteca e poderia me ajudar?<br><br><br>scr_fp =3D [(&#39=
;11001138433007&#39;, &#39;1&#39;, 1),(&#39;11001138433007&#39;, &#39;2&#39=
;, 0)]<br>&gt;&gt;&gt; item_param, user_param =3D irt(scr_fp)<br>2018-09-21=
 16:38:48 INFO: start loading data<br>start loading data<br>***************=
*********** [&#39;11001138433007&#39;, &#39;11001138433007&#39;] [&#39;1&#3=
9;, &#39;2&#39;] [1, 0]<br>2018-09-21 16:38:48 INFO: data loaded<br>data lo=
aded<br>100%|=E2=96=88=E2=96=88=E2=96=88=E2=96=88=E2=96=88=E2=96=88=E2=96=
=88=E2=96=88=E2=96=88=E2=96=88=E2=96=88=E2=96=88=E2=96=88=E2=96=88=E2=96=88=
=E2=96=88=E2=96=88=E2=96=88=E2=96=88=E2=96=88=E2=96=88=E2=96=88=E2=96=88=E2=
=96=88=E2=96=88=E2=96=88=E2=96=88=E2=96=88=E2=96=88=E2=96=88=E2=96=88=E2=96=
=88=E2=96=88=E2=96=88=E2=96=88=E2=96=88=E2=96=88=E2=96=88=E2=96=88=E2=96=88=
=E2=96=88=E2=96=88=E2=96=88=E2=96=88=E2=96=88=E2=96=88=E2=96=88=E2=96=88=E2=
=96=88=E2=96=88=E2=96=88=E2=96=88=E2=96=88=E2=96=88=E2=96=88=E2=96=88=E2=96=
=88=E2=96=88=E2=96=88=E2=96=88=E2=96=88=E2=96=88=E2=96=88=E2=96=88=E2=96=88=
=E2=96=88=E2=96=88=E2=96=88=E2=96=88=E2=96=88=E2=96=88=E2=96=88=E2=96=88=E2=
=96=88=E2=96=88=E2=96=88=E2=96=88=E2=96=88=E2=96=88=E2=96=88=E2=96=88=E2=96=
=88=E2=96=88=E2=96=88=E2=96=88=E2=96=88=E2=96=88=E2=96=88=E2=96=88=E2=96=88=
=E2=96=88=E2=96=88=E2=96=88=E2=96=88=E2=96=88=E2=96=88=E2=96=88=E2=96=88=E2=
=96=88=E2=96=88=E2=96=88=E2=96=88=E2=96=88=E2=96=88=E2=96=88=E2=96=88=E2=96=
=88=E2=96=88=E2=96=88=E2=96=88=E2=96=88=E2=96=88=E2=96=88=E2=96=88=E2=96=88=
=E2=96=88=E2=96=88=E2=96=88=E2=96=88=E2=96=88=E2=96=88=E2=96=88=E2=96=88=E2=
=96=88=E2=96=88=E2=96=88=E2=96=88=E2=96=88=E2=96=88=E2=96=88=E2=96=88=E2=96=
=88=E2=96=88=E2=96=88=E2=96=88=E2=96=88=E2=96=88=E2=96=88=E2=96=88=E2=96=88=
=E2=96=88=E2=96=88=E2=96=88=E2=96=88=E2=96=88=E2=96=88=E2=96=88=E2=96=88=E2=
=96=88=E2=96=88=E2=96=88=E2=96=88=E2=96=88=E2=96=88=E2=96=88=E2=96=88=E2=96=
=88=E2=96=88=E2=96=88=E2=96=88=E2=96=88=E2=96=88=E2=96=88=E2=96=88=E2=96=88=
=E2=96=88=E2=96=88=E2=96=88| 1/1 [00:00&lt;00:00, 639.77it/s]<br>=C2=A0 0%|=
=C2=A0=C2=A0=C2=A0=C2=A0=C2=A0=C2=A0=C2=A0=C2=A0=C2=A0=C2=A0=C2=A0=C2=A0=C2=
=A0=C2=A0=C2=A0=C2=A0=C2=A0=C2=A0=C2=A0=C2=A0=C2=A0=C2=A0=C2=A0=C2=A0=C2=A0=
=C2=A0=C2=A0=C2=A0=C2=A0=C2=A0=C2=A0=C2=A0=C2=A0=C2=A0=C2=A0=C2=A0=C2=A0=C2=
=A0=C2=A0=C2=A0=C2=A0=C2=A0=C2=A0=C2=A0=C2=A0=C2=A0=C2=A0=C2=A0=C2=A0=C2=A0=
=C2=A0=C2=A0=C2=A0=C2=A0=C2=A0=C2=A0=C2=A0=C2=A0=C2=A0=C2=A0=C2=A0=C2=A0=C2=
=A0=C2=A0=C2=A0=C2=A0=C2=A0=C2=A0=C2=A0=C2=A0=C2=A0=C2=A0=C2=A0=C2=A0=C2=A0=
=C2=A0=C2=A0=C2=A0=C2=A0=C2=A0=C2=A0=C2=A0=C2=A0=C2=A0=C2=A0=C2=A0=C2=A0=C2=
=A0=C2=A0=C2=A0=C2=A0=C2=A0=C2=A0=C2=A0=C2=A0=C2=A0=C2=A0=C2=A0=C2=A0=C2=A0=
=C2=A0=C2=A0=C2=A0=C2=A0=C2=A0=C2=A0=C2=A0=C2=A0=C2=A0=C2=A0=C2=A0=C2=A0=C2=
=A0=C2=A0=C2=A0=C2=A0=C2=A0=C2=A0=C2=A0=C2=A0=C2=A0=C2=A0=C2=A0=C2=A0=C2=A0=
=C2=A0=C2=A0=C2=A0=C2=A0=C2=A0=C2=A0=C2=A0=C2=A0=C2=A0=C2=A0=C2=A0=C2=A0=C2=
=A0=C2=A0=C2=A0=C2=A0=C2=A0=C2=A0=C2=A0=C2=A0=C2=A0=C2=A0=C2=A0=C2=A0=C2=A0=
=C2=A0=C2=A0=C2=A0=C2=A0=C2=A0=C2=A0=C2=A0=C2=A0=C2=A0=C2=A0=C2=A0=C2=A0=C2=
=A0=C2=A0=C2=A0=C2=A0=C2=A0=C2=A0=C2=A0=C2=A0=C2=A0=C2=A0=C2=A0=C2=A0=C2=A0=
=C2=A0 | 0/2 [00:00&lt;?, ?it/s]6666666666666666666666666666666666666CHAMAD=
AGET_MAP 0<br>TTTTTTTTTTTTTTTTTTTTTTTTTTTTTTGET_MAP3 [&#39;1&#39;, &#39;0&#=
39;]<br><br>--- Logging error ---<br>Traceback (most recent call last):<br>=
=C2=A0 File &quot;/home/graciela/descomplica/pyirt/pyirt/pyirt/solver/model=
.py&quot;, line 368, in update<br>=C2=A0=C2=A0=C2=A0 map_user_idx_vec =3D s=
elf.dao.get_map(item_idx, [&#39;1&#39;, &#39;0&#39;])<br>=C2=A0 File &quot;=
/home/graciela/descomplica/pyirt/pyirt/pyirt/dao.py&quot;, line 152, in get=
_map<br>=C2=A0=C2=A0=C2=A0 return [self.database.item2user_map[str(ans_key)=
][item_idx] for ans_key in ans_key_list]<br>=C2=A0 File &quot;/home/graciel=
a/descomplica/pyirt/pyirt/pyirt/dao.py&quot;, line 152, in &lt;listcomp&gt;=
<br>=C2=A0=C2=A0=C2=A0 return [self.database.item2user_map[str(ans_key)][it=
em_idx] for ans_key in ans_key_list]<br>KeyError: 0<br><br>During handling =
of the above exception, another exception occurred:<br><br>Traceback (most =
recent call last):<br>=C2=A0 File &quot;/usr/lib/python3.6/logging/__init__=
.py&quot;, line 993, in emit<br>=C2=A0=C2=A0=C2=A0 msg =3D self.format(reco=
rd)<br>=C2=A0 File &quot;/usr/lib/python3.6/logging/__init__.py&quot;, line=
 839, in format<br>=C2=A0=C2=A0=C2=A0 return fmt.format(record)<br>=C2=A0 F=
ile &quot;/usr/lib/python3.6/logging/__init__.py&quot;, line 576, in format=
<br>=C2=A0=C2=A0=C2=A0 record.message =3D record.getMessage()<br>=C2=A0 Fil=
e &quot;/usr/lib/python3.6/logging/__init__.py&quot;, line 338, in getMessa=
ge<br>=C2=A0=C2=A0=C2=A0 msg =3D msg % self.args<br>TypeError: not all argu=
ments converted during string formatting<br>Call stack:<br>=C2=A0 File &quo=
t;&lt;stdin&gt;&quot;, line 1, in &lt;module&gt;<br>=C2=A0 File &quot;/home=
/graciela/descomplica/pyirt/pyirt/pyirt/_pyirt.py&quot;, line 46, in irt<br=
>=C2=A0=C2=A0=C2=A0 mod.solve_EM()<br>=C2=A0 File &quot;/home/graciela/desc=
omplica/pyirt/pyirt/pyirt/solver/model.py&quot;, line 101, in solve_EM<br>=
=C2=A0=C2=A0=C2=A0 self._exp_step()<br>=C2=A0 File &quot;/home/graciela/des=
complica/pyirt/pyirt/pyirt/solver/model.py&quot;, line 161, in _exp_step<br=
>=C2=A0=C2=A0=C2=A0 self.__get_expect_count()<br>=C2=A0 File &quot;/home/gr=
aciela/descomplica/pyirt/pyirt/pyirt/solver/model.py&quot;, line 395, in __=
get_expect_count<br>=C2=A0=C2=A0=C2=A0 procs =3D procs_operator(procs, 7200=
, 0.1)<br>=C2=A0 File &quot;/home/graciela/descomplica/pyirt/pyirt/pyirt/so=
lver/model.py&quot;, line 27, in procs_operator<br>=C2=A0=C2=A0=C2=A0 p.sta=
rt()<br>=C2=A0 File &quot;/usr/lib/python3.6/multiprocessing/process.py&quo=
t;, line 105, in start<br>=C2=A0=C2=A0=C2=A0 self._popen =3D self._Popen(se=
lf)<br>=C2=A0 File &quot;/usr/lib/python3.6/multiprocessing/context.py&quot=
;, line 223, in _Popen<br>=C2=A0=C2=A0=C2=A0 return _default_context.get_co=
ntext().Process._Popen(process_obj)<br>=C2=A0 File &quot;/usr/lib/python3.6=
/multiprocessing/context.py&quot;, line 277, in _Popen<br>=C2=A0=C2=A0=C2=
=A0 return Popen(process_obj)<br>=C2=A0 File &quot;/usr/lib/python3.6/multi=
processing/popen_fork.py&quot;, line 19, in __init__<br>=C2=A0=C2=A0=C2=A0 =
self._launch(process_obj)<br>=C2=A0 File &quot;/usr/lib/python3.6/multiproc=
essing/popen_fork.py&quot;, line 73, in _launch<br>=C2=A0=C2=A0=C2=A0 code =
=3D process_obj._bootstrap()<br>=C2=A0 File &quot;/usr/lib/python3.6/multip=
rocessing/process.py&quot;, line 258, in _bootstrap<br>=C2=A0=C2=A0=C2=A0 s=
elf.run()<br>=C2=A0 File &quot;/usr/lib/python3.6/multiprocessing/process.p=
y&quot;, line 93, in run<br>=C2=A0=C2=A0=C2=A0 self._target(*self._args, **=
self._kwargs)<br>=C2=A0 File &quot;/home/graciela/descomplica/pyirt/pyirt/p=
yirt/solver/model.py&quot;, line 374, in update<br>=C2=A0=C2=A0=C2=A0 self.=
logger.critical(&quot;Unexpected error:&quot;, str(e))<br>Message: &#39;Une=
xpected error:&#39;<br>Arguments: (&#39;0&#39;,)<br>--- Logging error ---<b=
r>Traceback (most recent call last):<br>=C2=A0 File &quot;/home/graciela/de=
scomplica/pyirt/pyirt/pyirt/solver/model.py&quot;, line 368, in update<br>=
=C2=A0=C2=A0=C2=A0 map_user_idx_vec =3D self.dao.get_map(item_idx, [&#39;1&=
#39;, &#39;0&#39;])<br>=C2=A0 File &quot;/home/graciela/descomplica/pyirt/p=
yirt/pyirt/dao.py&quot;, line 152, in get_map<br>=C2=A0=C2=A0=C2=A0 return =
[self.database.item2user_map[str(ans_key)][item_idx] for ans_key in ans_key=
_list]<br>=C2=A0 File &quot;/home/graciela/descomplica/pyirt/pyirt/pyirt/da=
o.py&quot;, line 152, in &lt;listcomp&gt;<br>=C2=A0=C2=A0=C2=A0 return [sel=
f.database.item2user_map[str(ans_key)][item_idx] for ans_key in ans_key_lis=
t]<br>KeyError: 0<br><br>During handling of the above exception, another ex=
ception occurred:<br><br>Traceback (most recent call last):<br>=C2=A0 File =
&quot;/usr/lib/python3.6/logging/__init__.py&quot;, line 993, in emit<br>=
=C2=A0=C2=A0=C2=A0 msg =3D self.format(record)<br>=C2=A0 File &quot;/usr/li=
b/python3.6/logging/__init__.py&quot;, line 839, in format<br>=C2=A0=C2=A0=
=C2=A0 return fmt.format(record)<br>=C2=A0 File &quot;/usr/lib/python3.6/lo=
gging/__init__.py&quot;, line 576, in format<br>=C2=A0=C2=A0=C2=A0 record.m=
essage =3D record.getMessage()<br>=C2=A0 File &quot;/usr/lib/python3.6/logg=
ing/__init__.py&quot;, line 338, in getMessage<br>=C2=A0=C2=A0=C2=A0 msg =
=3D msg % self.args<br>TypeError: not all arguments converted during string=
 formatting<br>Call stack:<br>=C2=A0 File &quot;&lt;stdin&gt;&quot;, line 1=
, in &lt;module&gt;<br>=C2=A0 File &quot;/home/graciela/descomplica/pyirt/p=
yirt/pyirt/_pyirt.py&quot;, line 46, in irt<br>=C2=A0=C2=A0=C2=A0 mod.solve=
_EM()<br>=C2=A0 File &quot;/home/graciela/descomplica/pyirt/pyirt/pyirt/sol=
ver/model.py&quot;, line 101, in solve_EM<br>=C2=A0=C2=A0=C2=A0 self._exp_s=
tep()<br>=C2=A0 File &quot;/home/graciela/descomplica/pyirt/pyirt/pyirt/sol=
ver/model.py&quot;, line 161, in _exp_step<br>=C2=A0=C2=A0=C2=A0 self.__get=
_expect_count()<br>=C2=A0 File &quot;/home/graciela/descomplica/pyirt/pyirt=
/pyirt/solver/model.py&quot;, line 395, in __get_expect_count<br>=C2=A0=C2=
=A0=C2=A0 procs =3D procs_operator(procs, 7200, 0.1)<br>=C2=A0 File &quot;/=
home/graciela/descomplica/pyirt/pyirt/pyirt/solver/model.py&quot;, line 27,=
 in procs_operator<br>=C2=A0=C2=A0=C2=A0 p.start()<br>=C2=A0 File &quot;/us=
r/lib/python3.6/multiprocessing/process.py&quot;, line 105, in start<br>=C2=
=A0=C2=A0=C2=A0 self._popen =3D self._Popen(self)<br>=C2=A0 File &quot;/usr=
/lib/python3.6/multiprocessing/context.py&quot;, line 223, in _Popen<br>=C2=
=A0=C2=A0=C2=A0 return _default_context.get_context().Process._Popen(proces=
s_obj)<br>=C2=A0 File &quot;/usr/lib/python3.6/multiprocessing/context.py&q=
uot;, line 277, in _Popen<br>=C2=A0=C2=A0=C2=A0 return Popen(process_obj)<b=
r>=C2=A0 File &quot;/usr/lib/python3.6/multiprocessing/popen_fork.py&quot;,=
 line 19, in __init__<br>=C2=A0=C2=A0=C2=A0 self._launch(process_obj)<br>=
=C2=A0 File &quot;/usr/lib/python3.6/multiprocessing/popen_fork.py&quot;, l=
ine 73, in _launch<br>=C2=A0=C2=A0=C2=A0 code =3D process_obj._bootstrap()<=
br>=C2=A0 File &quot;/usr/lib/python3.6/multiprocessing/process.py&quot;, l=
ine 258, in _bootstrap<br>=C2=A0=C2=A0=C2=A0 self.run()<br>=C2=A0 File &quo=
t;/usr/lib/python3.6/multiprocessing/process.py&quot;, line 93, in run<br>=
=C2=A0=C2=A0=C2=A0 self._target(*self._args, **self._kwargs)<br>=C2=A0 File=
 &quot;/home/graciela/descomplica/pyirt/pyirt/pyirt/solver/model.py&quot;, =
line 374, in update<br>=C2=A0=C2=A0=C2=A0 self.logger.critical(&quot;Unexpe=
cted error:&quot;, str(e))<br>Message: &#39;Unexpected error:&#39;<br>Argum=
ents: (&#39;0&#39;,)<br>Process Process-4:<br>Traceback (most recent call l=
ast):<br>=C2=A0 File &quot;/usr/lib/python3.6/multiprocessing/process.py&qu=
ot;, line 258, in _bootstrap<br>=C2=A0=C2=A0=C2=A0 self.run()<br>=C2=A0 Fil=
e &quot;/usr/lib/python3.6/multiprocessing/process.py&quot;, line 93, in ru=
n<br>=C2=A0=C2=A0=C2=A0 self._target(*self._args, **self._kwargs)<br>=C2=A0=
 File &quot;/home/graciela/descomplica/pyirt/pyirt/pyirt/solver/model.py&qu=
ot;, line 375, in update<br>=C2=A0=C2=A0=C2=A0 raise e<br>=C2=A0 File &quot=
;/home/graciela/descomplica/pyirt/pyirt/pyirt/solver/model.py&quot;, line 3=
68, in update<br>=C2=A0=C2=A0=C2=A0 map_user_idx_vec =3D self.dao.get_map(i=
tem_idx, [&#39;1&#39;, &#39;0&#39;])<br>=C2=A0 File &quot;/home/graciela/de=
scomplica/pyirt/pyirt/pyirt/dao.py&quot;, line 152, in get_map<br>=C2=A0=C2=
=A0=C2=A0 return [self.database.item2user_map[str(ans_key)][item_idx] for a=
ns_key in ans_key_list]<br>=C2=A0 File &quot;/home/graciela/descomplica/pyi=
rt/pyirt/pyirt/dao.py&quot;, line 152, in &lt;listcomp&gt;<br>=C2=A0=C2=A0=
=C2=A0 return [self.database.item2user_map[str(ans_key)][item_idx] for ans_=
key in ans_key_list]<br>KeyError: 0<br>Traceback (most recent call last):<b=
r>=C2=A0 File &quot;&lt;stdin&gt;&quot;, line 1, in &lt;module&gt;<br>=C2=
=A0 File &quot;/home/graciela/descomplica/pyirt/pyirt/pyirt/_pyirt.py&quot;=
, line 46, in irt<br>=C2=A0=C2=A0=C2=A0 mod.solve_EM()<br>=C2=A0 File &quot=
;/home/graciela/descomplica/pyirt/pyirt/pyirt/solver/model.py&quot;, line 1=
01, in solve_EM<br>=C2=A0=C2=A0=C2=A0 self._exp_step()<br>=C2=A0 File &quot=
;/home/graciela/descomplica/pyirt/pyirt/pyirt/solver/model.py&quot;, line 1=
61, in _exp_step<br>=C2=A0=C2=A0=C2=A0 self.__get_expect_count()<br>=C2=A0 =
File &quot;/home/graciela/descomplica/pyirt/pyirt/pyirt/solver/model.py&quo=
t;, line 400, in __get_expect_count<br>=C2=A0=C2=A0=C2=A0 self.item_expecte=
d_right_by_theta[:, item_idx] =3D procs_repo[item_idx][1]<br>=C2=A0 File &q=
uot;&lt;string&gt;&quot;, line 2, in __getitem__<br>=C2=A0 File &quot;/usr/=
lib/python3.6/multiprocessing/managers.py&quot;, line 772, in _callmethod<b=
r>=C2=A0=C2=A0=C2=A0 raise convert_to_error(kind, result)</div><div>KeyErro=
r: 0<br></div></div>

<p></p>

-- <br />
-- <br />
------------------------------------<br />
Grupo Python-Brasil<br />
<a href=3D"https://wiki.python.org.br/AntesDePerguntar">https://wiki.python=
.org.br/AntesDePerguntar</a><br />
&nbsp;<br />
&lt;*&gt; Para visitar o site do grupo na web, acesse:<br />
    <a href=3D"http://groups.google.com/group/python-brasil">http://groups.=
google.com/group/python-brasil</a><br />
&nbsp;<br />
&lt;*&gt; Para sair deste grupo, envie um e-mail para:<br />
    python-brasil+unsubscribe@googlegroups.com<br />
--- <br />
Voc=C3=AA recebeu essa mensagem porque est=C3=A1 inscrito no grupo &quot;Py=
thon Brasil&quot; dos Grupos do Google.<br />
Para cancelar inscri=C3=A7=C3=A3o nesse grupo e parar de receber e-mails de=
le, envie um e-mail para <a href=3D"mailto:python-brasil+unsubscribe@google=
groups.com">python-brasil+unsubscribe@googlegroups.com</a>.<br />
Para postar nesse grupo, envie um e-mail para <a href=3D"mailto:python-bras=
il@googlegroups.com">python-brasil@googlegroups.com</a>.<br />
Para ver essa discuss=C3=A3o na Web, acesse <a href=3D"https://groups.googl=
e.com/d/msgid/python-brasil/f05b452f-ada9-4980-bc81-e938ed3c4a94%40googlegr=
oups.com?utm_medium=3Demail&utm_source=3Dfooter">https://groups.google.com/=
d/msgid/python-brasil/f05b452f-ada9-4980-bc81-e938ed3c4a94%40googlegroups.c=
om</a>.<br />
Para mais op=C3=A7=C3=B5es, acesse <a href=3D"https://groups.google.com/d/o=
ptout">https://groups.google.com/d/optout</a>.<br />

------=_Part_1027_574696549.1537560212376--

------=_Part_1026_185157175.1537560212376--
